Traceback (most recent call last):
  File "C:\Users\Alexander\anaconda3\lib\site-packages\jupyter_cache\executors\utils.py", line 51, in single_nb_execution
    executenb(
  File "C:\Users\Alexander\anaconda3\lib\site-packages\nbclient\client.py", line 1112, in execute
    return NotebookClient(nb=nb, resources=resources, km=km, **kwargs).execute()
  File "C:\Users\Alexander\anaconda3\lib\site-packages\nbclient\util.py", line 74, in wrapped
    return just_run(coro(*args, **kwargs))
  File "C:\Users\Alexander\anaconda3\lib\site-packages\nbclient\util.py", line 53, in just_run
    return loop.run_until_complete(coro)
  File "C:\Users\Alexander\anaconda3\lib\asyncio\base_events.py", line 642, in run_until_complete
    return future.result()
  File "C:\Users\Alexander\anaconda3\lib\site-packages\nbclient\client.py", line 553, in async_execute
    await self.async_execute_cell(
  File "C:\Users\Alexander\anaconda3\lib\site-packages\nbclient\client.py", line 857, in async_execute_cell
    self._check_raise_for_error(cell, exec_reply)
  File "C:\Users\Alexander\anaconda3\lib\site-packages\nbclient\client.py", line 760, in _check_raise_for_error
    raise CellExecutionError.from_cell_and_msg(cell, exec_reply_content)
nbclient.exceptions.CellExecutionError: An error occurred while executing the following cell:
------------------
# loading relevant packages
import numpy as np
import pandas as pd
import matplotlib.pyplot as plt
from matplotlib.pyplot import figure
import seaborn as sns
import random
import math
import statsmodels.formula.api as smf
from sklearn.metrics import mean_squared_error
from sklearn.linear_model import LinearRegression
from sklearn.preprocessing import PolynomialFeatures
from sklearn.model_selection import train_test_split
from sklearn.model_selection import GridSearchCV
from sklearn.metrics import make_scorer
from sklearn.model_selection import cross_val_score
from sklearn.model_selection import KFold
from sklearn.preprocessing import StandardScaler
from sklearn.linear_model import Ridge
import statsmodels.api as sm
from scipy.stats import norm
import warnings
from SyncRNG import SyncRNG
warnings.filterwarnings('ignore')
%matplotlib inline
------------------

[1;31m---------------------------------------------------------------------------[0m
[1;31mModuleNotFoundError[0m                       Traceback (most recent call last)
[1;32mC:\Users\ALEXAN~1\AppData\Local\Temp/ipykernel_36396/2957225731.py[0m in [0;36m<module>[1;34m[0m
[0;32m     21[0m [1;32mfrom[0m [0mscipy[0m[1;33m.[0m[0mstats[0m [1;32mimport[0m [0mnorm[0m[1;33m[0m[1;33m[0m[0m
[0;32m     22[0m [1;32mimport[0m [0mwarnings[0m[1;33m[0m[1;33m[0m[0m
[1;32m---> 23[1;33m [1;32mfrom[0m [0mSyncRNG[0m [1;32mimport[0m [0mSyncRNG[0m[1;33m[0m[1;33m[0m[0m
[0m[0;32m     24[0m [0mwarnings[0m[1;33m.[0m[0mfilterwarnings[0m[1;33m([0m[1;34m'ignore'[0m[1;33m)[0m[1;33m[0m[1;33m[0m[0m
[0;32m     25[0m [0mget_ipython[0m[1;33m([0m[1;33m)[0m[1;33m.[0m[0mrun_line_magic[0m[1;33m([0m[1;34m'matplotlib'[0m[1;33m,[0m [1;34m'inline'[0m[1;33m)[0m[1;33m[0m[1;33m[0m[0m

[1;31mModuleNotFoundError[0m: No module named 'SyncRNG'
ModuleNotFoundError: No module named 'SyncRNG'

