Traceback (most recent call last):
  File "C:\Users\Alexander\anaconda3\lib\site-packages\jupyter_cache\executors\utils.py", line 51, in single_nb_execution
    executenb(
  File "C:\Users\Alexander\anaconda3\lib\site-packages\nbclient\client.py", line 1112, in execute
    return NotebookClient(nb=nb, resources=resources, km=km, **kwargs).execute()
  File "C:\Users\Alexander\anaconda3\lib\site-packages\nbclient\util.py", line 74, in wrapped
    return just_run(coro(*args, **kwargs))
  File "C:\Users\Alexander\anaconda3\lib\site-packages\nbclient\util.py", line 53, in just_run
    return loop.run_until_complete(coro)
  File "C:\Users\Alexander\anaconda3\lib\asyncio\base_events.py", line 642, in run_until_complete
    return future.result()
  File "C:\Users\Alexander\anaconda3\lib\site-packages\nbclient\client.py", line 553, in async_execute
    await self.async_execute_cell(
  File "C:\Users\Alexander\anaconda3\lib\site-packages\nbclient\client.py", line 857, in async_execute_cell
    self._check_raise_for_error(cell, exec_reply)
  File "C:\Users\Alexander\anaconda3\lib\site-packages\nbclient\client.py", line 760, in _check_raise_for_error
    raise CellExecutionError.from_cell_and_msg(cell, exec_reply_content)
nbclient.exceptions.CellExecutionError: An error occurred while executing the following cell:
------------------
import random
import pandas as pd
import numpy as np
from scipy.stats import norm

import statsmodels.api as sm
import statsmodels.formula.api as smf
import patsy
from SyncRNG import SyncRNG
import numpy as np
import re
from statsmodels.sandbox.stats.multicomp import multipletests
from scipy import linalg
from itertools import chain

from SyncRNG import SyncRNG

from CTL.causal_tree_learn import CausalTree
from sklearn.model_selection import train_test_split
import plotnine as p
import seaborn as sns
import matplotlib.pyplot as plt
import matplotlib.patches as mpatches
------------------

[1;31m---------------------------------------------------------------------------[0m
[1;31mModuleNotFoundError[0m                       Traceback (most recent call last)
[1;32mC:\Users\ALEXAN~1\AppData\Local\Temp/ipykernel_24892/2508031605.py[0m in [0;36m<module>[1;34m[0m
[0;32m      7[0m [1;32mimport[0m [0mstatsmodels[0m[1;33m.[0m[0mformula[0m[1;33m.[0m[0mapi[0m [1;32mas[0m [0msmf[0m[1;33m[0m[1;33m[0m[0m
[0;32m      8[0m [1;32mimport[0m [0mpatsy[0m[1;33m[0m[1;33m[0m[0m
[1;32m----> 9[1;33m [1;32mfrom[0m [0mSyncRNG[0m [1;32mimport[0m [0mSyncRNG[0m[1;33m[0m[1;33m[0m[0m
[0m[0;32m     10[0m [1;32mimport[0m [0mnumpy[0m [1;32mas[0m [0mnp[0m[1;33m[0m[1;33m[0m[0m
[0;32m     11[0m [1;32mimport[0m [0mre[0m[1;33m[0m[1;33m[0m[0m

[1;31mModuleNotFoundError[0m: No module named 'SyncRNG'
ModuleNotFoundError: No module named 'SyncRNG'

